<?xml version="1.0" encoding="utf-8"?>
<!-- =================================================================================== -->
<!-- |    This document was autogenerated by xacro from example_robot_assignment_aloukeri.urdf.xacro | -->
<!-- |    EDITING THIS FILE BY HAND IS NOT RECOMMENDED                                 | -->
<!-- =================================================================================== -->
<robot name="robot">
  <material name="white">
    <color rgba="1 1 1 1"/>
  </material>
  <material name="orange">
    <color rgba="1 0.3 0.1 1"/>
  </material>
  <material name="blue">
    <color rgba="0.2 0.2 1 1"/>
  </material>
  <link name="world"/>
  <joint name="base_joint" type="fixed">
    <origin rpy="0 0 0" xyz="1.5 1.0 0"/>
    <parent link="world"/>
    <child link="base_link"/>
  </joint>
  <link name="base_link">
    <visual>
      <origin rpy="0 0 0" xyz="0 0 0.05"/>
      <geometry>
        <box size="2.5 1.5 0.1"/>
      </geometry>
      <material name="green">
        <color rgba="0.2 1 0.2 1"/>
      </material>
    </visual>
    <collision>
      <origin rpy="0 0 0" xyz="0 0 0.05"/>
      <geometry>
        <box size="2.5 1.5 0.1"/>
      </geometry>
    </collision>
    <inertial>
      <origin rpy="0 0 0" xyz="0 0 0.05"/>
      <mass value="12"/>
      <inertia ixx="2.26" ixy="0.0" ixz="0.0" iyy="6.26" iyz="0.0" izz="8.5"/>
    </inertial>
  </link>
  <link name="slider_x_link">
    <inertial>
      <origin rpy="0 0 0" xyz="0 0 0"/>
      <mass value="0.01"/>
      <inertia ixx="0.001" ixy="0" ixz="0" iyy="0.001" iyz="0" izz="0.001"/>
    </inertial>
  </link>
  <joint name="slider_x_joint" type="prismatic">
    <origin rpy="0 0 0" xyz="-1.25 0 0.1"/>
    <parent link="base_link"/>
    <child link="slider_x_link"/>
    <axis xyz="1 0 0"/>
    <limit effort="100" lower="0" upper="2" velocity="100"/>
  </joint>
  <joint name="slider_y_joint" type="prismatic">
    <origin rpy="0 0 0" xyz="0 0 0"/>
    <parent link="slider_x_link"/>
    <child link="slider_link"/>
    <axis xyz="0 1 0"/>
    <limit effort="100" lower="-0.6" upper="0.6" velocity="100"/>
  </joint>
  <link name="slider_link">
    <visual>
      <origin rpy="0 0 0" xyz="0 0 0.5"/>
      <geometry>
        <box size="0.5 0.25 1.0"/>
      </geometry>
      <material name="blue"/>
    </visual>
    <collision>
      <origin rpy="0 0 0" xyz="0 0 0.5"/>
      <geometry>
        <box size="0.5 0.25 1.0"/>
      </geometry>
    </collision>
    <inertial>
      <origin rpy="0 0 0" xyz="0 0 0.5"/>
      <mass value="0.5"/>
      <inertia ixx="0.0442708333333" ixy="0.0" ixz="0.0" iyy="0.0520833333333" iyz="0.0" izz="0.0130208333333"/>
    </inertial>
  </link>
  <joint name="arm_joint" type="revolute">
    <origin rpy="0 0 0" xyz="0.25 0 1.0"/>
    <parent link="slider_link"/>
    <child link="arm_link"/>
    <axis xyz="0 -1 0"/>
    <limit effort="100" lower="-1.57079632679" upper="0" velocity="100"/>
  </joint>
  <link name="arm_link">
    <visual>
      <origin rpy="0 1.57079632679 0" xyz="0.5 0 0"/>
      <geometry>
        <cylinder length="1" radius="0.1"/>
      </geometry>
      <material name="orange"/>
    </visual>
    <collision>
      <origin rpy="0 1.57079632679 0" xyz="0.5 0 0"/>
      <geometry>
        <cylinder length="1" radius="0.1"/>
      </geometry>
    </collision>
    <inertial>
      <origin rpy="0 1.57079632679 0" xyz="0.5 0 0"/>
      <mass value="1.0"/>
      <inertia ixx="0.0858333333333" ixy="0.0" ixz="0.0" iyy="0.0858333333333" iyz="0.0" izz="0.005"/>
    </inertial>
  </link>
  <joint name="camera_joint" type="fixed">
    <origin rpy="0 0 0" xyz="1 0 0.175"/>
    <parent link="arm_link"/>
    <child link="camera_link"/>
  </joint>
  <link name="camera_link">
    <visual>
      <origin rpy="0 0 0" xyz="-0.03 0 0"/>
      <geometry>
        <box size="0.06 0.15 0.15"/>
      </geometry>
      <material name="white"/>
    </visual>
    <visual>
      <origin rpy="0 1.57079632679 0" xyz="0.03 0 0"/>
      <geometry>
        <cylinder length="0.06" radius="0.04"/>
      </geometry>
      <material name="blue"/>
    </visual>
    <collision>
      <origin rpy="0 0 0" xyz="0.0 0 0"/>
      <geometry>
        <box size="0.12 0.15 0.15"/>
      </geometry>
    </collision>
    <inertial>
      <origin rpy="0 0 0" xyz="0.0 0 0"/>
      <mass value="0.1"/>
      <inertia ixx="0.000375" ixy="0.0" ixz="0.0" iyy="0.0003075" iyz="0.0" izz="0.0003075"/>
    </inertial>
  </link>
</robot>

